Workbook

Sheet Executive Summary
B3: PORTFOLIO ANALYSIS
B5: Risk & Return Portfolio Project
B7: Companies: Apple | KO |NFLX | BRK.B| DIS |IBM |VZ | WMT | GE |TSLA |Benchmark: S&P 500|
B10: Portfolio Overview | G10: Risk Vs Return Chart
B11: Number of Stocks | C11: 10
B12: Potfolio Value Assumed | C12: 1000000
B13: Benchmark | C13: S&P 500
B14: Risk Free Rate | C14: 0.04
B15: Analysis Period | C15: 01/12-12/17
B23: PERFORMANCE PORTFOLIO COMPARISON
B26: Portfolio | C26: Expected Return | D26: Volatility | E26: Sharpe Ratio | F26: Beta
B27: Equal Weight Portfolio | C27: ='Summary Table'!C5 -> 0.1891 | D27: ='Summary Table'!D5 -> 0.1354 | E27: ='Summary Table'!E5 -> 1.1 | F27: ='Summary Table'!F5 -> 0.924
B28: Max Sharpe Portfolio | C28: ='Summary Table'!C6 -> 0.29704018 | D28: ='Summary Table'!D6 -> 0.18740045 | E28: ='Summary Table'!E6 -> 1.3716092 | F28: ='Summary Table'!F6 -> 1.0408936
B29: Minimum Variance Portfolio | C29: ='Summary Table'!C7 -> 0.12891772 | D29: ='Summary Table'!D7 -> 0.11222796 | E29: ='Summary Table'!E7 -> 0.79229561 | F29: ='Summary Table'!F7 -> 0.79229561
B32: PORTOFLIO ALLOCATION | J32: VALUE AT RISK (VaR)
J34: Confidence Level | K34: VaR | L34: 10 day VaR
J35: 0.95 | K35: ='Parametric VaR'!C12 -> 13374.44 | L35: =K35*SQRT(10) -> 42293.692
J36: 0.99 | K36: ='Parametric VaR'!C13 -> 19197.996 | L36: =K36*SQRT(10) -> 60709.392
B45: EQUAL WEIGHT PORTFOLIO | D45: MINIMUM VARIANCE PORTFOLIO | F45: MAXIMIZE SHARPE RATIO PORTFOLIO
B48: Executive Summary:
B49: This project presents a comprehensive portfolio risk and return analysis using a diversified set of ten large-cap companies: Apple (AAPL), Coca-Cola (KO), Netflix (NFLX), Berkshire Hathaway (BRK.B), Walt Disney (DIS), IBM, Verizon (VZ), Walmart (WMT), General Electric (GE), and Tesla (TSLA). The objective of the analysis is to evaluate individual stock performance, construct diversified portfolios, and assess portfolio risk using quantitative financial models. The study begins with an analysis of individual stock returns, volatility, and beta values, providing insights into the risk–return characteristics of each security relative to the market benchmark (S&P 500). Stocks such as Tesla and Netflix exhibit higher expected returns but also significantly higher volatility, while companies like Coca-Cola and Verizon demonstrate more stable, defensive characteristics. Using these securities, three portfolio strategies were constructed and evaluated: an Equal Weighted Portfolio, a Return-Optimized Portfolio, and a Minimum Variance Portfolio. Portfolio performance was assessed using key financial metrics including expected return, volatility, Sharpe Ratio, portfolio beta, and Jensen’s Alpha. The analysis demonstrates how diversification and portfolio optimization techniques can improve risk-adjusted returns. Risk management was further examined through the application of Value at Risk (VaR) using the variance–covariance approach. This measure estimates the potential downside risk of the portfolio at different confidence levels and time horizons, providing insight into the potential losses under adverse market conditions. Overall, the project highlights the practical application of Modern Portfolio Theory, CAPM-based risk measures, and portfolio optimization techniques to construct efficient portfolios and evaluate investment risk.
B68: Key Insights:
B69: • Diversification reduces portfolio volatility • Optimization improves risk-adjusted performance • Defensive stocks stabilize portfolio returns • Growth stocks increase expected return but add volatility

Sheet Closing Price Data & Returns 
B1: Price Data | AI1: Returns
B3: AAPL | E3: KO | H3: NFLX | K3: BRK.B | N3: DIS | Q3: IBM | T3: VZ | W3: WMT | Z3: GE | AC3: TSLA | AF3: S&P 500 | AI3: R-AAPL | AJ3: R-KO | AK3: R-NFLX | AL3: R-BRKB | AM3: R-DIS | AN3: R-IBM | AO3: R_VZ | AP3: R-WMT | AQ3: R_GE | AR3: R_TSLA | AS3: R_S&P 500
B4: Date | C4: Close | E4: Date | F4: Close | H4: Date | I4: Close | K4: Date | L4: Close | N4: Date | O4: Close | Q4: Date | R4: Close | T4: Date | U4: Close | W4: Date | X4: Close | Z4: Date | AA4: Close | AC4: Date | AD4: Close | AF4: Date | AG4: Close
B5: 40911.667 | C5: 14.69 | E5: 40911.667 | F5: 35.07 | H5: 40911.667 | I5: 1.03 | K5: 40911.667 | L5: 77.68 | N5: 40911.667 | O5: 38.31 | Q5: 40911.667 | R5: 177.95 | T5: 40911.667 | U5: 39.73 | W5: 40911.667 | X5: 20.11 | Z5: 40911.667 | AA5: 91.6 | AC5: 40911.667 | AD5: 1.87 | AF5: 40911.667 | AG5: 1277.06
B6: 40912.667 | C6: 14.77 | E6: 40912.667 | F6: 34.85 | H6: 40912.667 | I6: 1.15 | K6: 40912.667 | L6: 76.8 | N6: 40912.667 | O6: 38.85 | Q6: 40912.667 | R6: 177.22 | T6: 40912.667 | U6: 39.21 | W6: 40912.667 | X6: 19.9 | Z6: 40912.667 | AA6: 92.6 | AC6: 40912.667 | AD6: 1.85 | AF6: 40912.667 | AG6: 1277.3 | AI6: =C6/C5-1 -> 0.0054458816 | AJ6: =F6/F5-1 -> -0.0062731679 | AK6: =I6/I5-1 -> 0.11650485 | AL6: =L6/L5-1 -> -0.011328527 | AM6: =O6/O5-1 -> 0.014095536 | AN6: =R6/R5-1 -> -0.0041022759 | AO6: =U6/U5-1 -> -0.013088346 | AP6: =X6/X5-1 -> -0.010442566 | AQ6: =AA6/AA5-1 -> 0.010917031 | AR6: =AD6/AD5-1 -> -0.010695187 | AS6: =AG6/AG5-1 -> 0.00018793166
B7: 40913.667 | C7: 14.93 | E7: 40913.667 | F7: 34.69 | H7: 40913.667 | I7: 1.13 | K7: 40913.667 | L7: 76.93 | N7: 40913.667 | O7: 39.5 | Q7: 40913.667 | R7: 176.38 | T7: 40913.667 | U7: 38.94 | W7: 40913.667 | X7: 19.81 | Z7: 40913.667 | AA7: 92.55 | AC7: 40913.667 | AD7: 1.81 | AF7: 40913.667 | AG7: 1281.06 | AI7: =C7/C6-1 -> 0.010832769 | AJ7: =F7/F6-1 -> -0.0045911047 | AK7: =I7/I6-1 -> -0.017391304 | AL7: =L7/L6-1 -> 0.0016927083 | AM7: =O7/O6-1 -> 0.016731017 | AN7: =R7/R6-1 -> -0.0047398713 | AO7: =U7/U6-1 -> -0.0068859985 | AP7: =X7/X6-1 -> -0.0045226131 | AQ7: =AA7/AA6-1 -> -0.0005399568 | AR7: =AD7/AD6-1 -> -0.021621622 | AS7: =AG7/AG6-1 -> 0.0029437094
B8: 40914.667 | C8: 15.09 | E8: 40914.667 | F8: 34.47 | H8: 40914.667 | I8: 1.23 | K8: 40914.667 | L8: 76.39 | N8: 40914.667 | O8: 39.91 | Q8: 40914.667 | R8: 174.36 | T8: 40914.667 | U8: 38.33 | W8: 40914.667 | X8: 19.67 | Z8: 40914.667 | AA8: 93.04 | AC8: 40914.667 | AD8: 1.79 | AF8: 40914.667 | AG8: 1277.81 | AI8: =C8/C7-1 -> 0.010716678 | AJ8: =F8/F7-1 -> -0.0063418853 | AK8: =I8/I7-1 -> 0.088495575 | AL8: =L8/L7-1 -> -0.0070193683 | AM8: =O8/O7-1 -> 0.010379747 | AN8: =R8/R7-1 -> -0.011452546 | AO8: =U8/U7-1 -> -0.015665126 | AP8: =X8/X7-1 -> -0.0070671378 | AQ8: =AA8/AA7-1 -> 0.0052944354 | AR8: =AD8/AD7-1 -> -0.011049724 | AS8: =AG8/AG7-1 -> -0.0025369616
B9: 40917.667 | C9: 15.06 | E9: 40917.667 | F9: 34.47 | H9: 40917.667 | I9: 1.4 | K9: 40917.667 | L9: 76.29 | N9: 40917.667 | O9: 39.75 | Q9: 40917.667 | R9: 173.45 | T9: 40917.667 | U9: 38.37 | W9: 40917.667 | X9: 19.73 | Z9: 40917.667 | AA9: 94.09 | AC9: 40917.667 | AD9: 1.82 | AF9: 40917.667 | AG9: 1280.7 | AI9: =C9/C8-1 -> -0.0019880716 | AJ9: =F9/F8-1 -> 0 | AK9: =I9/I8-1 -> 0.13821138 | AL9: =L9/L8-1 -> -0.0013090719 | AM9: =O9/O8-1 -> -0.0040090203 | AN9: =R9/R8-1 -> -0.0052190869 | AO9: =U9/U8-1 -> 0.001043569 | AP9: =X9/X8-1 -> 0.0030503305 | AQ9: =AA9/AA8-1 -> 0.011285469 | AR9: =AD9/AD8-1 -> 0.016759777 | AS9: =AG9/AG8-1 -> 0.0022616821
B10: 40918.667 | C10: 15.12 | E10: 40918.667 | F10: 34.67 | H10: 40918.667 | I10: 1.37 | K10: 40918.667 | L10: 77.42 | N10: 40918.667 | O10: 39.63 | Q10: 40918.667 | R10: 173.18 | T10: 40918.667 | U10: 38.57 | W10: 40918.667 | X10: 19.68 | Z10: 40918.667 | AA10: 93.39 | AC10: 40918.667 | AD10: 1.84 | AF10: 40918.667 | AG10: 1292.08 | AI10: =C10/C9-1 -> 0.0039840637 | AJ10: =F10/F9-1 -> 0.0058021468 | AK10: =I10/I9-1 -> -0.021428571 | AL10: =L10/L9-1 -> 0.014811902 | AM10: =O10/O9-1 -> -0.0030188679 | AN10: =R10/R9-1 -> -0.0015566446 | AO10: =U10/U9-1 -> 0.0052124055 | AP10: =X10/X9-1 -> -0.0025342119 | AQ10: =AA10/AA9-1 -> -0.0074396854 | AR10: =AD10/AD9-1 -> 0.010989011 | AS10: =AG10/AG9-1 -> 0.0088857656
B11: 40919.667 | C11: 15.09 | E11: 40919.667 | F11: 34.03 | H11: 40919.667 | I11: 1.32 | K11: 40919.667 | L11: 78 | N11: 40919.667 | O11: 38.7 | Q11: 40919.667 | R11: 174.15 | T11: 40919.667 | U11: 38.9 | W11: 40919.667 | X11: 19.8 | Z11: 40919.667 | AA11: 94.19 | AC11: 40919.667 | AD11: 1.88 | AF11: 40919.667 | AG11: 1292.48 | AI11: =C11/C10-1 -> -0.001984127 | AJ11: =F11/F10-1 -> -0.018459763 | AK11: =I11/I10-1 -> -0.03649635 | AL11: =L11/L10-1 -> 0.0074916042 | AM11: =O11/O10-1 -> -0.02346707 | AN11: =R11/R10-1 -> 0.0056011087 | AO11: =U11/U10-1 -> 0.0085558724 | AP11: =X11/X10-1 -> 0.006097561 | AQ11: =AA11/AA10-1 -> 0.0085662276 | AR11: =AD11/AD10-1 -> 0.02173913 | AS11: =AG11/AG10-1 -> 0.00030957835
B12: 40920.667 | C12: 15.05 | E12: 40920.667 | F12: 33.78 | H12: 40920.667 | I12: 1.32 | K12: 40920.667 | L12: 78.5 | N12: 40920.667 | O12: 38.73 | Q12: 40920.667 | R12: 172.45 | T12: 40920.667 | U12: 38.92 | W12: 40920.667 | X12: 19.83 | Z12: 40920.667 | AA12: 94.44 | AC12: 40920.667 | AD12: 1.88 | AF12: 40920.667 | AG12: 1295.5 | AI12: =C12/C11-1 -> -0.0026507621 | AJ12: =F12/F11-1 -> -0.007346459 | AK12: =I12/I11-1 -> 0 | AL12: =L12/L11-1 -> 0.0064102564 | AM12: =O12/O11-1 -> 0.0007751938 | AN12: =R12/R11-1 -> -0.0097616997 | AO12: =U12/U11-1 -> 0.00051413882 | AP12: =X12/X11-1 -> 0.0015151515 | AQ12: =AA12/AA11-1 -> 0.0026542096 | AR12: =AD12/AD11-1 -> 0 | AS12: =AG12/AG11-1 -> 0.0023365932
B13: 40921.667 | C13: 14.99 | E13: 40921.667 | F13: 33.49 | H13: 40921.667 | I13: 1.35 | K13: 40921.667 | L13: 77.77 | N13: 40921.667 | O13: 38.4 | Q13: 40921.667 | R13: 171.13 | T13: 40921.667 | U13: 38.92 | W13: 40921.667 | X13: 19.85 | Z13: 40921.667 | AA13: 93.99 | AC13: 40921.667 | AD13: 1.52 | AF13: 40921.667 | AG13: 1289.09 | AI13: =C13/C12-1 -> -0.003986711 | AJ13: =F13/F12-1 -> -0.0085849615 | AK13: =I13/I12-1 -> 0.022727273 | AL13: =L13/L12-1 -> -0.0092993631 | AM13: =O13/O12-1 -> -0.0085205267 | AN13: =R13/R12-1 -> -0.0076543926 | AO13: =U13/U12-1 -> 0 | AP13: =X13/X12-1 -> 0.0010085729 | AQ13: =AA13/AA12-1 -> -0.0047649301 | AR13: =AD13/AD12-1 -> -0.19148936 | AS13: =AG13/AG12-1 -> -0.0049478966
B14: 40925.667 | C14: 15.17 | E14: 40925.667 | F14: 33.67 | H14: 40925.667 | I14: 1.35 | K14: 40925.667 | L14: 77.97 | N14: 40925.667 | O14: 38.48 | Q14: 40925.667 | R14: 171.93 | T14: 40925.667 | U14: 39.02 | W14: 40925.667 | X14: 19.95 | Z14: 40925.667 | AA14: 93.49 | AC14: 40925.667 | AD14: 1.77 | AF14: 40925.667 | AG14: 1293.67 | AI14: =C14/C13-1 -> 0.012008005 | AJ14: =F14/F13-1 -> 0.0053747387 | AK14: =I14/I13-1 -> 0 | AL14: =L14/L13-1 -> 0.0025716857 | AM14: =O14/O13-1 -> 0.0020833333 | AN14: =R14/R13-1 -> 0.0046748086 | AO14: =U14/U13-1 -> 0.0025693731 | AP14: =X14/X13-1 -> 0.0050377834 | AQ14: =AA14/AA13-1 -> -0.0053197149 | AR14: =AD14/AD13-1 -> 0.16447368 | AS14: =AG14/AG13-1 -> 0.0035528939
B15: 40926.667 | C15: 15.33 | E15: 40926.667 | F15: 33.8 | H15: 40926.667 | I15: 1.41 | K15: 40926.667 | L15: 78.92 | N15: 40926.667 | O15: 39.02 | Q15: 40926.667 | R15: 172.95 | T15: 40926.667 | U15: 39.01 | W15: 40926.667 | X15: 20 | Z15: 40926.667 | AA15: 94.89 | AC15: 40926.667 | AD15: 1.79 | AF15: 40926.667 | AG15: 1308.04 | AI15: =C15/C14-1 -> 0.010547132 | AJ15: =F15/F14-1 -> 0.0038610039 | AK15: =I15/I14-1 -> 0.044444444 | AL15: =L15/L14-1 -> 0.012184173 | AM15: =O15/O14-1 -> 0.014033264 | AN15: =R15/R14-1 -> 0.005932647 | AO15: =U15/U14-1 -> -0.00025627883 | AP15: =X15/X14-1 -> 0.0025062657 | AQ15: =AA15/AA14-1 -> 0.014974864 | AR15: =AD15/AD14-1 -> 0.011299435 | AS15: =AG15/AG14-1 -> 0.011107933
B16: 40927.667 | C16: 15.28 | E16: 40927.667 | F16: 33.73 | H16: 40927.667 | I16: 1.48 | K16: 40927.667 | L16: 79.59 | N16: 40927.667 | O16: 39.44 | Q16: 40927.667 | R16: 172.43 | T16: 40927.667 | U16: 39 | W16: 40927.667 | X16: 20.2 | Z16: 40927.667 | AA16: 95.54 | AC16: 40927.667 | AD16: 1.78 | AF16: 40927.667 | AG16: 1314.5 | AI16: =C16/C15-1 -> -0.0032615786 | AJ16: =F16/F15-1 -> -0.0020710059 | AK16: =I16/I15-1 -> 0.04964539 | AL16: =L16/L15-1 -> 0.0084896097 | AM16: =O16/O15-1 -> 0.010763711 | AN16: =R16/R15-1 -> -0.0030066493 | AO16: =U16/U15-1 -> -0.00025634453 | AP16: =X16/X15-1 -> 0.01 | AQ16: =AA16/AA15-1 -> 0.0068500369 | AR16: =AD16/AD15-1 -> -0.0055865922 | AS16: =AG16/AG15-1 -> 0.0049386869
B17: 40928.667 | C17: 15.01 | E17: 40928.667 | F17: 34.05 | H17: 40928.667 | I17: 1.43 | K17: 40928.667 | L17: 79.91 | N17: 40928.667 | O17: 39.31 | Q17: 40928.667 | R17: 180.07 | T17: 40928.667 | U17: 38.97 | W17: 40928.667 | X17: 20.34 | Z17: 40928.667 | AA17: 95.54 | AC17: 40928.667 | AD17: 1.77 | AF17: 40928.667 | AG17: 1315.38 | AI17: =C17/C16-1 -> -0.017670157 | AJ17: =F17/F16-1 -> 0.0094871035 | AK17: =I17/I16-1 -> -0.033783784 | AL17: =L17/L16-1 -> 0.0040206056 | AM17: =O17/O16-1 -> -0.003296146 | AN17: =R17/R16-1 -> 0.044307835 | AO17: =U17/U16-1 -> -0.00076923077 | AP17: =X17/X16-1 -> 0.0069306931 | AQ17: =AA17/AA16-1 -> 0 | AR17: =AD17/AD16-1 -> -0.0056179775 | AS17: =AG17/AG16-1 -> 0.00066945607
... B538: 41688.667 | C538: 19.5 | E538: 41688.667 | F538: 37.47 | H538: 41688.667 | I538: 6.24 | K538: 41688.667 | L538: 114.73 | N538: 41688.667 | O538: 79.58 | Q538: 41688.667 | R538: 174.98 | T538: 41688.667 | U538: 45.98 | W538: 41688.667 | X538: 25.11 | Z538: 41688.667 | AA538: 127.97 | AC538: 41688.667 | AD538: 13.58 | AF538: 41688.667 | AG538: 1840.76 | AI538: =C538/C537-1 -> 0.0036026763 | AJ538: =F538/F537-1 -> -0.037503211 | AK538: =I538/I537-1 -> 0.0032154341 | AL538: =L538/L537-1 -> -0.0019138756 | AM538: =O538/O537-1 -> 0.0044175186 | AN538: =R538/R537-1 -> -0.0026788259 | AO538: =U538/U537-1 -> -0.011395399 | AP538: =X538/X537-1 -> -0.0059382423 | AQ538: =AA538/AA537-1 -> -0.0035041271 | AR538: =AD538/AD537-1 -> 0.027231467 | AS538: =AG538/AG537-1 -> 0.0011584713
B539: 41689.667 | C539: 19.19 | E539: 41689.667 | F539: 37.1 | H539: 41689.667 | I539: 6.12 | K539: 41689.667 | L539: 113.36 | N539: 41689.667 | O539: 78.87 | Q539: 41689.667 | R539: 174.75 | T539: 41689.667 | U539: 46.53 | W539: 41689.667 | X539: 24.95 | Z539: 41689.667 | AA539: 126.72 | AC539: 41689.667 | AD539: 12.91 | AF539: =AC539 -> 41689.667 | AG539: =AG538 -> 1840.76 | AI539: =C539/C538-1 -> -0.015897436 | AJ539: =F539/F538-1 -> -0.0098745663 | AK539: =I539/I538-1 -> -0.019230769 | AL539: =L539/L538-1 -> -0.011941079 | AM539: =O539/O538-1 -> -0.0089218397 | AN539: =R539/R538-1 -> -0.0013144359 | AO539: =U539/U538-1 -> 0.011961722 | AP539: =X539/X538-1 -> -0.0063719634 | AQ539: =AA539/AA538-1 -> -0.0097679144 | AR539: =AD539/AD538-1 -> -0.049337261 | AS539: =AG539/AG538-1 -> 0
B540: 41690.667 | C540: 18.97 | E540: 41690.667 | F540: 37.3 | H540: 41690.667 | I540: 6.21 | K540: 41690.667 | L540: 113.1 | N540: 41690.667 | O540: 79.19 | Q540: 41690.667 | R540: 176 | T540: 41690.667 | U540: 48.12 | W540: 41690.667 | X540: 24.51 | Z540: 41690.667 | AA540: 125.32 | AC540: 41690.667 | AD540: 14 | AF540: 41690.667 | AG540: 1839.78 | AI540: =C540/C539-1 -> -0.011464304 | AJ540: =F540/F539-1 -> 0.0053908356 | AK540: =I540/I539-1 -> 0.014705882 | AL540: =L540/L539-1 -> -0.002293578 | AM540: =O540/O539-1 -> 0.0040573095 | AN540: =R540/R539-1 -> 0.0071530758 | AO540: =U540/U539-1 -> 0.034171502 | AP540: =X540/X539-1 -> -0.017635271 | AQ540: =AA540/AA539-1 -> -0.01104798 | AR540: =AD540/AD539-1 -> 0.084430674 | AS540: =AG540/AG539-1 -> -0.0005323888
B541: 41691.667 | C541: 18.76 | E541: 41691.667 | F541: 37.18 | H541: 41691.667 | I541: 6.17 | K541: 41691.667 | L541: 113.18 | N541: 41691.667 | O541: 80.13 | Q541: 41691.667 | R541: 174.59 | T541: 41691.667 | U541: 47.27 | W541: 41691.667 | X541: 24.37 | Z541: 41691.667 | AA541: 124.42 | AC541: 41691.667 | AD541: 13.97 | AF541: 41691.667 | AG541: 1836.25 | AI541: =C541/C540-1 -> -0.011070111 | AJ541: =F541/F540-1 -> -0.0032171582 | AK541: =I541/I540-1 -> -0.0064412238 | AL541: =L541/L540-1 -> 0.00070733864 | AM541: =O541/O540-1 -> 0.011870186 | AN541: =R541/R540-1 -> -0.0080113636 | AO541: =U541/U540-1 -> -0.017664173 | AP541: =X541/X540-1 -> -0.0057119543 | AQ541: =AA541/AA540-1 -> -0.0071816151 | AR541: =AD541/AD540-1 -> -0.0021428571 | AS541: =AG541/AG540-1 -> -0.0019187077
B542: 41694.667 | C542: 18.84 | E542: 41694.667 | F542: 37.5 | H542: 41694.667 | I542: 6.39 | K542: 41694.667 | L542: 113.2 | N542: 41694.667 | O542: 80.73 | Q542: 41694.667 | R542: 175.22 | T542: 41694.667 | U542: 46.23 | W542: 41694.667 | X542: 24.45 | Z542: 41694.667 | AA542: 126.17 | AC542: 41694.667 | AD542: 14.51 | AF542: 41694.667 | AG542: 1847.61 | AI542: =C542/C541-1 -> 0.0042643923 | AJ542: =F542/F541-1 -> 0.0086067778 | AK542: =I542/I541-1 -> 0.035656402 | AL542: =L542/L541-1 -> 0.00017670967 | AM542: =O542/O541-1 -> 0.0074878323 | AN542: =R542/R541-1 -> 0.0036084541 | AO542: =U542/U541-1 -> -0.022001269 | AP542: =X542/X541-1 -> 0.0032827247 | AQ542: =AA542/AA541-1 -> 0.014065263 | AR542: =AD542/AD541-1 -> 0.038654259 | AS542: =AG542/AG541-1 -> 0.0061865214
B543: 41695.667 | C543: 18.65 | E543: 41695.667 | F543: 37.77 | H543: 41695.667 | I543: 6.47 | K543: 41695.667 | L543: 113.94 | N543: 41695.667 | O543: 80.21 | Q543: 41695.667 | R543: 175.01 | T543: 41695.667 | U543: 46.29 | W543: 41695.667 | X543: 24.45 | Z543: 41695.667 | AA543: 126.07 | AC543: 41695.667 | AD543: 16.53 | AF543: 41695.667 | AG543: 1845.12 | AI543: =C543/C542-1 -> -0.010084926 | AJ543: =F543/F542-1 -> 0.0072 | AK543: =I543/I542-1 -> 0.012519562 | AL543: =L543/L542-1 -> 0.0065371025 | AM543: =O543/O542-1 -> -0.0064412238 | AN543: =R543/R542-1 -> -0.0011984933 | AO543: =U543/U542-1 -> 0.0012978585 | AP543: =X543/X542-1 -> 0 | AQ543: =AA543/AA542-1 -> -0.00079258144 | AR543: =AD543/AD542-1 -> 0.13921433 | AS543: =AG543/AG542-1 -> -0.001347687
B544: 41696.667 | C544: 18.48 | E544: 41696.667 | F544: 37.87 | H544: 41696.667 | I544: 6.41 | K544: 41696.667 | L544: 113.7 | N544: 41696.667 | O544: 80.08 | Q544: 41696.667 | R544: 175.81 | T544: 41696.667 | U544: 46.35 | W544: 41696.667 | X544: 24.93 | Z544: 41696.667 | AA544: 126.22 | AC544: 41696.667 | AD544: 16.87 | AF544: 41696.667 | AG544: 1845.16 | AI544: =C544/C543-1 -> -0.0091152815 | AJ544: =F544/F543-1 -> 0.0026476039 | AK544: =I544/I543-1 -> -0.0092735703 | AL544: =L544/L543-1 -> -0.0021063718 | AM544: =O544/O543-1 -> -0.0016207455 | AN544: =R544/R543-1 -> 0.0045711674 | AO544: =U544/U543-1 -> 0.0012961763 | AP544: =X544/X543-1 -> 0.019631902 | AQ544: =AA544/AA543-1 -> 0.0011898152 | AR544: =AD544/AD543-1 -> 0.020568663 | AS544: =AG544/AG543-1 -> 2.1678807e-05
B545: 41697.667 | C545: 18.85 | E545: 41697.667 | F545: 38.07 | H545: 41697.667 | I545: 6.46 | K545: 41697.667 | L545: 114.58 | N545: 41697.667 | O545: 80.48 | Q545: 41697.667 | R545: 176.96 | T545: 41697.667 | U545: 47.5 | W545: 41697.667 | X545: 24.85 | Z545: 41697.667 | AA545: 127.22 | AC545: 41697.667 | AD545: 16.84 | AF545: 41697.667 | AG545: 1854.29 | AI545: =C545/C544-1 -> 0.020021645 | AJ545: =F545/F544-1 -> 0.0052812252 | AK545: =I545/I544-1 -> 0.007800312 | AL545: =L545/L544-1 -> 0.0077396658 | AM545: =O545/O544-1 -> 0.004995005 | AN545: =R545/R544-1 -> 0.0065411524 | AO545: =U545/U544-1 -> 0.024811219 | AP545: =X545/X544-1 -> -0.0032089852 | AQ545: =AA545/AA544-1 -> 0.0079226747 | AR545: =AD545/AD544-1 -> -0.0017783047 | AS545: =AG545/AG544-1 -> 0.0049480804
B546: 41698.667 | C546: 18.79 | E546: 41698.667 | F546: 38.2 | H546: 41698.667 | I546: 6.37 | K546: 41698.667 | L546: 115.78 | N546: 41698.667 | O546: 80.81 | Q546: 41698.667 | R546: 176.87 | T546: 41698.667 | U546: 47.58 | W546: 41698.667 | X546: 24.9 | Z546: 41698.667 | AA546: 127.07 | AC546: 41698.667 | AD546: 16.32 | AF546: 41698.667 | AG546: 1859.45 | AI546: =C546/C545-1 -> -0.0031830239 | AJ546: =F546/F545-1 -> 0.0034147623 | AK546: =I546/I545-1 -> -0.013931889 | AL546: =L546/L545-1 -> 0.010473032 | AM546: =O546/O545-1 -> 0.0041003976 | AN546: =R546/R545-1 -> -0.00050858951 | AO546: =U546/U545-1 -> 0.0016842105 | AP546: =X546/X545-1 -> 0.0020120724 | AQ546: =AA546/AA545-1 -> -0.0011790599 | AR546: =AD546/AD545-1 -> -0.03087886 | AS546: =AG546/AG545-1 -> 0.0027827362
B547: 41701.667 | C547: 18.85 | E547: 41701.667 | F547: 38.12 | H547: 41701.667 | I547: 6.37 | K547: 41701.667 | L547: 116.06 | N547: 41701.667 | O547: 79.46 | Q547: 41701.667 | R547: 176 | T547: 41701.667 | U547: 47.31 | W547: 41701.667 | X547: 24.71 | Z547: 41701.667 | AA547: 125.32 | AC547: 41701.667 | AD547: 16.7 | AF547: 41701.667 | AG547: 1845.73 | AI547: =C547/C546-1 -> 0.0031931879 | AJ547: =F547/F546-1 -> -0.0020942408 | AK547: =I547/I546-1 -> 0 | AL547: =L547/L546-1 -> 0.0024183797 | AM547: =O547/O546-1 -> -0.016705853 | AN547: =R547/R546-1 -> -0.004918867 | AO547: =U547/U546-1 -> -0.0056746532 | AP547: =X547/X546-1 -> -0.0076305221 | AQ547: =AA547/AA546-1 -> -0.013771937 | AR547: =AD547/AD546-1 -> 0.023284314 | AS547: =AG547/AG546-1 -> -0.0073785259
B548: 41702.667 | C548: 18.97 | E548: 41702.667 | F548: 38.31 | H548: 41702.667 | I548: 6.5 | K548: 41702.667 | L548: 118.57 | N548: 41702.667 | O548: 81.71 | Q548: 41702.667 | R548: 178.08 | T548: 41702.667 | U548: 47.9 | W548: 41702.667 | X548: 25.04 | Z548: 41702.667 | AA548: 127.97 | AC548: 41702.667 | AD548: 16.99 | AF548: 41702.667 | AG548: 1873.91 | AI548: =C548/C547-1 -> 0.0063660477 | AJ548: =F548/F547-1 -> 0.0049842602 | AK548: =I548/I547-1 -> 0.020408163 | AL548: =L548/L547-1 -> 0.021626745 | AM548: =O548/O547-1 -> 0.028316134 | AN548: =R548/R547-1 -> 0.011818182 | AO548: =U548/U547-1 -> 0.012470936 | AP548: =X548/X547-1 -> 0.013354917 | AQ548: =AA548/AA547-1 -> 0.021145867 | AR548: =AD548/AD547-1 -> 0.017365269 | AS548: =AG548/AG547-1 -> 0.015267672
B549: 41703.667 | C549: 19.01 | E549: 41703.667 | F549: 38.35 | H549: 41703.667 | I549: 6.48 | K549: 41703.667 | L549: 118.98 | N549: 41703.667 | O549: 82.68 | Q549: 41703.667 | R549: 178.75 | T549: 41703.667 | U549: 47.38 | W549: 41703.667 | X549: 24.93 | Z549: 41703.667 | AA549: 129.36 | AC549: 41703.667 | AD549: 16.84 | AF549: 41703.667 | AG549: 1873.81 | AI549: =C549/C548-1 -> 0.0021085925 | AJ549: =F549/F548-1 -> 0.0010441138 | AK549: =I549/I548-1 -> -0.0030769231 | AL549: =L549/L548-1 -> 0.003457873 | AM549: =O549/O548-1 -> 0.011871252 | AN549: =R549/R548-1 -> 0.003762354 | AO549: =U549/U548-1 -> -0.01085595 | AP549: =X549/X548-1 -> -0.0043929712 | AQ549: =AA549/AA548-1 -> 0.010861921 | AR549: =AD549/AD548-1 -> -0.0088287228 | AS549: =AG549/AG548-1 -> -5.3364356e-05
B550: 41704.667 | C550: 18.96 | E550: 41704.667 | F550: 38.47 | H550: 41704.667 | I550: 6.44 | K550: 41704.667 | L550: 121.2 | N550: 41704.667 | O550: 83.34 | Q550: 41704.667 | R550: 179.23 | T550: 41704.667 | U550: 47.46 | W550: 41704.667 | X550: 24.96 | Z550: 41704.667 | AA550: 130.81 | AC550: 41704.667 | AD550: 16.86 | AF550: 41704.667 | AG550: 1877.03 | AI550: =C550/C549-1 -> -0.0026301946 | AJ550: =F550/F549-1 -> 0.0031290743 | AK550: =I550/I549-1 -> -0.0061728395 | AL550: =L550/L549-1 -> 0.018658598 | AM550: =O550/O549-1 -> 0.0079825835 | AN550: =R550/R549-1 -> 0.0026853147 | AO550: =U550/U549-1 -> 0.0016884762 | AP550: =X550/X549-1 -> 0.0012033694 | AQ550: =AA550/AA549-1 -> 0.011209029 | AR550: =AD550/AD549-1 -> 0.0011876485 | AS550: =AG550/AG549-1 -> 0.001718424
B551: 41705.667 | C551: 18.94 | E551: 41705.667 | F551: 38.55 | H551: 41705.667 | I551: 6.41 | K551: 41705.667 | L551: 122.67 | N551: 41705.667 | O551: 82.21 | Q551: 41705.667 | R551: 179.27 | T551: 41705.667 | U551: 47.15 | W551: 41705.667 | X551: 24.86 | Z551: 41705.667 | AA551: 130.36 | AC551: 41705.667 | AD551: 16.41 | AF551: 41705.667 | AG551: 1878.04 | AI551: =C551/C550-1 -> -0.0010548523 | AJ551: =F551/F550-1 -> 0.0020795425 | AK551: =I551/I550-1 -> -0.0046583851 | AL551: =L551/L550-1 -> 0.012128713 | AM551: =O551/O550-1 -> -0.013558915 | AN551: =R551/R550-1 -> 0.00022317692 | AO551: =U551/U550-1 -> -0.0065318163 | AP551: =X551/X550-1 -> -0.0040064103 | AQ551: =AA551/AA550-1 -> -0.003440104 | AR551: =AD551/AD550-1 -> -0.026690391 | AS551: =AG551/AG550-1 -> 0.0005380841
... B1513: 43098.667 | C1513: 42.31 | E1513: 43098.667 | F1513: 45.88 | H1513: 43098.667 | I1513: 19.2 | K1513: 43098.667 | L1513: 198.22 | N1513: 43098.667 | O1513: 107.51 | Q1513: 43098.667 | R1513: 146.54 | T1513: 43098.667 | U1513: 52.93 | W1513: 43098.667 | X1513: 32.92 | Z1513: 43098.667 | AA1513: 87.06 | AC1513: 43098.667 | AD1513: 20.76 | AF1513: 43098.667 | AG1513: 2673.61 | AI1513: =C1513/C1512-1 -> -0.010755202 | AJ1513: =F1513/F1512-1 -> 0.0034995626 | AK1513: =I1513/I1512-1 -> -0.0036325895 | AL1513: =L1513/L1512-1 -> -0.0067147725 | AM1513: =O1513/O1512-1 -> -0.0024125452 | AN1513: =R1513/R1512-1 -> -0.0040100591 | AO1513: =U1513/U1512-1 -> -0.0093580386 | AP1513: =X1513/X1512-1 -> -0.0063386659 | AQ1513: =AA1513/AA1512-1 -> 0.0051957049 | AR1513: =AD1513/AD1512-1 -> -0.012369172 | AS1513: =AG1513/AG1512-1 -> -0.0051831787

Sheet Return&Risk of Individual Stock
C3: Average Return | D3: Annualized Return | E3: Risk / Stdev of Individual Stock | F3: Annualized STDEV
B4: AAPL | C4: =AVERAGE('Closing Price Data & Returns '!AI6:AI1513) -> 0.00082509413 | D4: =C4*250 -> 0.20627353 | E4: =_xlfn.STDEV.S('Closing Price Data & Returns '!AI6:AI1513) -> 0.015696405 | F4: =E4*SQRT(250) -> 0.24818195
B5: KO | C5: =AVERAGE('Closing Price Data & Returns '!AJ6:AJ1513) -> 0.00021593065 | D5: =C5*250 -> 0.053982662 | E5: =_xlfn.STDEV.S('Closing Price Data & Returns '!AJ6:AJ1513) -> 0.0086837977 | F5: =E5*SQRT(250) -> 0.1373029
B6: NFLX | C6: =AVERAGE('Closing Price Data & Returns '!AK6:AK1513) -> 0.0024538896 | D6: =C6*250 -> 0.61347239 | E6: =_xlfn.STDEV.S('Closing Price Data & Returns '!AK6:AK1513) -> 0.03257915 | F6: =E6*SQRT(250) -> 0.51512159
B7: BRK.B | C7: =AVERAGE('Closing Price Data & Returns '!AL6:AL1513) -> 0.00066112187 | D7: =C7*250 -> 0.16528047 | E7: =_xlfn.STDEV.S('Closing Price Data & Returns '!AL6:AL1513) -> 0.008922499 | F7: =E7*SQRT(250) -> 0.1410771
B8: DIS | C8: =AVERAGE('Closing Price Data & Returns '!AM6:AM1513) -> 0.00075044785 | D8: =C8*250 -> 0.18761196 | E8: =_xlfn.STDEV.S('Closing Price Data & Returns '!AM6:AM1513) -> 0.011471059 | F8: =E8*SQRT(250) -> 0.18137337
B9: IBM | C9: =AVERAGE('Closing Price Data & Returns '!AN6:AN1513) -> -6.2442054e-05 | D9: =C9*250 -> -0.015610513 | E9: =_xlfn.STDEV.S('Closing Price Data & Returns '!AN6:AN1513) -> 0.011494934 | F9: =E9*SQRT(250) -> 0.18175087
B10: VZ | C10: =AVERAGE('Closing Price Data & Returns '!AO6:AO1513) -> 0.0002415176 | D10: =C10*250 -> 0.0603794 | E10: =_xlfn.STDEV.S('Closing Price Data & Returns '!AO6:AO1513) -> 0.010136588 | F10: =E10*SQRT(250) -> 0.16027354
B11: WMT | C11: =AVERAGE('Closing Price Data & Returns '!AP6:AP1513) -> 0.00038410406 | D11: =C11*250 -> 0.096026016 | E11: =_xlfn.STDEV.S('Closing Price Data & Returns '!AP6:AP1513) -> 0.010712912 | F11: =E11*SQRT(250) -> 0.16938601
B12: GE | C12: =AVERAGE('Closing Price Data & Returns '!AQ6:AQ1513) -> 3.4261518e-05 | D12: =C12*250 -> 0.0085653795 | E12: =_xlfn.STDEV.S('Closing Price Data & Returns '!AQ6:AQ1513) -> 0.011672011 | F12: =E12*SQRT(250) -> 0.1845507
B13: TSLA | C13: =AVERAGE('Closing Price Data & Returns '!AR6:AR1513) -> 0.0020585426 | D13: =C13*250 -> 0.51463565 | E13: =_xlfn.STDEV.S('Closing Price Data & Returns '!AR6:AR1513) -> 0.030520698 | F13: =E13*SQRT(250) -> 0.48257461
B14: S&P 500 | C14: =AVERAGE('Closing Price Data & Returns '!AS6:AS1513) -> 0.00051878196 | D14: =C14*250 -> 0.12969549 | E14: =_xlfn.STDEV.S('Closing Price Data & Returns '!AS6:AS1513) -> 0.0075743905 | F14: =E14*SQRT(250) -> 0.11976163
B16: Interpretation
B17: The table compares the average returns and risk levels of individual stocks relative to the S&P 500 benchmark. The results highlight a clear risk–return tradeoff across the assets. Stocks such as NFLX and TSLA deliver the highest annualized returns (61.35% and 51.46%), but they also exhibit significantly higher volatility, with annualized standard deviations exceeding 48–51%, indicating higher investment risk. In contrast, defensive stocks like KO and BRK.B provide more stable returns with lower volatility, making them relatively less risky investments. The S&P 500 benchmark shows a balanced profile with an annualized return of 12.97% and volatility of 11.98%, reflecting the benefits of diversification across the broader market. Notably, IBM shows a negative annualized return (-1.56%), suggesting underperformance during the analyzed period. Overall, the analysis demonstrates that higher potential returns are generally associated with higher levels of risk, reinforcing the importance of diversification when constructing an optimal investment portfolio.

Sheet Calculating the Individual BETA
B2: R-AAPL | C2: R-KO | D2: R-NFLX | E2: R-BRKB | F2: R-DIS | G2: R-IBM | H2: R_VZ | I2: R-WMT | J2: R_GE | K2: R_TSLA | L2: R_S&P 500 | N2: Metrics | O2: AAPL | P2: KO | Q2: NFLX | R2: BRKB | S2: DIS | T2: IBM | U2: VZ | V2: WMT | W2: GE | X2: TSLA | Y2: S&P 500
N3: Variance | O3: =_xlfn.VAR.S(B5:B1512) -> 0.00024637712 | P3: =_xlfn.VAR.S(C5:C1512) -> 7.5408343e-05 | Q3: =_xlfn.VAR.S(D5:D1512) -> 0.001061401 | R3: =_xlfn.VAR.S(E5:E1512) -> 7.9610989e-05 | S3: =_xlfn.VAR.S(F5:F1512) -> 0.00013158519 | T3: =_xlfn.VAR.S(G5:G1512) -> 0.00013213351 | U3: =_xlfn.VAR.S(H5:H1512) -> 0.00010275043 | V3: =_xlfn.VAR.S(I5:I1512) -> 0.00011476648 | ... Y3: =_xlfn.VAR.S(L5:L1512) -> 5.7371392e-05
N4: Covaraince with Index | O4: =COVAR(B5:B1512,$L$5:$L$1512) -> 5.9380029e-05 | P4: =COVAR(C5:C1512,$L$5:$L$1512) -> 3.4889356e-05 | Q4: =COVAR(D5:D1512,$L$5:$L$1512) -> 7.1816859e-05 | R4: =COVAR(E5:E1512,$L$5:$L$1512) -> 5.3717692e-05 | S4: =COVAR(F5:F1512,$L$5:$L$1512) -> 5.4844237e-05 | T4: =COVAR(G5:G1512,$L$5:$L$1512) -> 5.0027986e-05 | U4: =COVAR(H5:H1512,$L$5:$L$1512) -> 3.6697244e-05 | V4: =COVAR(I5:I1512,$L$5:$L$1512) -> 3.1718734e-05 | ... Y4: =COVAR(L5:L1512,$L$5:$L$1512) -> 5.7333347e-05
B5: 0.0054458816 | C5: -0.0062731679 | D5: 0.11650485 | E5: -0.011328527 | F5: 0.014095536 | G5: -0.0041022759 | H5: -0.013088346 | I5: -0.010442566 | J5: 0.010917031 | K5: -0.010695187 | L5: 0.00018793166 | N5: Beta | O5: =O4/$Y$3 -> 1.0350111 | P5: =P4/$Y$3 -> 0.60813159 | Q5: =Q4/$Y$3 -> 1.2517887 | R5: =R4/$Y$3 -> 0.93631496 | S5: =S4/$Y$3 -> 0.95595096 | T5: =T4/$Y$3 -> 0.87200231 | U5: =U4/$Y$3 -> 0.6396436 | V5: =V4/$Y$3 -> 0.55286673 | ... Y5: =Y4/$Y$3 -> 0.99933687
B6: 0.010832769 | C6: -0.0045911047 | D6: -0.017391304 | E6: 0.0016927083 | F6: 0.016731017 | G6: -0.0047398713 | H6: -0.0068859985 | I6: -0.0045226131 | J6: -0.0005399568 | K6: -0.021621622 | L6: 0.0029437094
B7: 0.010716678 | C7: -0.0063418853 | D7: 0.088495575 | E7: -0.0070193683 | F7: 0.010379747 | G7: -0.011452546 | H7: -0.015665126 | I7: -0.0070671378 | J7: 0.0052944354 | K7: -0.011049724 | L7: -0.0025369616 | N7: Interpretation:
B8: -0.0019880716 | C8: 0 | D8: 0.13821138 | E8: -0.0013090719 | F8: -0.0040090203 | G8: -0.0052190869 | H8: 0.001043569 | I8: 0.0030503305 | J8: 0.011285469 | K8: 0.016759777 | L8: 0.0022616821 | N8: This table presents the systematic risk (Beta) of each stock relative to the S&P 500 market index. Beta measures the sensitivity of a stock’s returns to movements in the overall market and is calculated using the ratio of the covariance between the stock and the market to the variance of the market index. Stocks with Beta greater than 1 are considered more volatile than the market and tend to amplify market movements. In this analysis, TSLA (1.372) and NFLX (1.252) exhibit the highest betas, indicating that these stocks are more sensitive to market fluctuations and carry higher systematic risk. Stocks with Beta close to 1, such as AAPL (1.035) and GE (1.013), tend to move broadly in line with the market. These stocks generally reflect market-level risk exposure. Conversely, stocks with Beta below 1, including KO (0.608), VZ (0.640), and WMT (0.553), demonstrate lower sensitivity to market movements and are typically considered defensive stocks, offering relatively more stability during market volatility. Overall, the results highlight how different stocks contribute varying levels of systematic market risk, which is an important consideration when constructing a diversified investment portfolio.
B9: 0.0039840637 | C9: 0.0058021468 | D9: -0.021428571 | E9: 0.014811902 | F9: -0.0030188679 | G9: -0.0015566446 | H9: 0.0052124055 | I9: -0.0025342119 | J9: -0.0074396854 | K9: 0.010989011 | L9: 0.0088857656
B10: -0.001984127 | C10: -0.018459763 | D10: -0.03649635 | E10: 0.0074916042 | F10: -0.02346707 | G10: 0.0056011087 | H10: 0.0085558724 | I10: 0.006097561 | J10: 0.0085662276 | K10: 0.02173913 | L10: 0.00030957835
B11: -0.0026507621 | C11: -0.007346459 | D11: 0 | E11: 0.0064102564 | F11: 0.0007751938 | G11: -0.0097616997 | H11: 0.00051413882 | I11: 0.0015151515 | J11: 0.0026542096 | K11: 0 | L11: 0.0023365932
B12: -0.003986711 | C12: -0.0085849615 | D12: 0.022727273 | E12: -0.0092993631 | F12: -0.0085205267 | G12: -0.0076543926 | H12: 0 | I12: 0.0010085729 | J12: -0.0047649301 | K12: -0.19148936 | L12: -0.0049478966
B13: 0.012008005 | C13: 0.0053747387 | D13: 0 | E13: 0.0025716857 | F13: 0.0020833333 | G13: 0.0046748086 | H13: 0.0025693731 | I13: 0.0050377834 | J13: -0.0053197149 | K13: 0.16447368 | L13: 0.0035528939
B14: 0.010547132 | C14: 0.0038610039 | D14: 0.044444444 | E14: 0.012184173 | F14: 0.014033264 | G14: 0.005932647 | H14: -0.00025627883 | I14: 0.0025062657 | J14: 0.014974864 | K14: 0.011299435 | L14: 0.011107933
B15: -0.0032615786 | C15: -0.0020710059 | D15: 0.04964539 | E15: 0.0084896097 | F15: 0.010763711 | G15: -0.0030066493 | H15: -0.00025634453 | I15: 0.01 | J15: 0.0068500369 | K15: -0.0055865922 | L15: 0.0049386869
B16: -0.017670157 | C16: 0.0094871035 | D16: -0.033783784 | E16: 0.0040206056 | F16: -0.003296146 | G16: 0.044307835 | H16: -0.00076923077 | I16: 0.0069306931 | J16: 0 | K16: -0.0056179775 | L16: 0.00066945607
B17: 0.016655563 | C17: 0.0064610866 | D17: -0.062937063 | E17: -0.0095106995 | F17: -0.0015263292 | G17: 0.0077192203 | H17: -0.014626636 | I17: -0.0019665683 | J17: -0.010990161 | K17: 0.0056497175 | L17: 0.00047134668
B18: -0.0163827 | C18: -0.0093376131 | D18: -0.014925373 | E18: -0.00846494 | F18: 0 | G18: 0.010250193 | H18: -0.015885417 | I18: 0.0078817734 | J18: -0.0052915652 | K18: 0.028089888 | L18: -0.0010410334
B19: 0.062624917 | C19: 0.0079528719 | D19: 0.03030303 | E19: 0.017456677 | F19: 0.0078980892 | G19: -0.001036439 | H19: -0.0026462027 | I19: 0.0014662757 | J19: 0.015427173 | K19: 0.016393443 | L19: 0.0086944616
B20: -0.0043887147 | C20: -0.0061367621 | D20: 0.22058824 | E20: -0.0023794615 | F20: -0.0053083923 | G20: -0.0038770272 | H20: -0.0092862828 | I20: -0.0082967301 | J20: -0.0031433361 | K20: 0.037634409 | L20: -0.0057388052
... B22: 0.013149656 | C22: 0.00029655991 | D22: 0.011299435 | E22: -0.0091916394 | F22: -0.0066242038 | G22: 0.010718997 | H22: 0.010749798 | I22: 0.0093873518 | J22: -0.0068464293 | K22: 0.0051020408 | L22: -0.0025069892
B23: 0.0074165637 | C23: 0.0011858879 | D23: -0.039106145 | E23: -0.0040665904 | F23: -0.0023082842 | G23: 0.00048947626 | H23: 0.0013294337 | I23: 0.00097895252 | J23: -0.0100753 | K23: -0.015228426 | L23: -0.00047219387 | N23: Stock | O23: Beta | P23: Market Line
B24: -0.00061349693 | C24: 0.0044418123 | D24: 0.023255814 | E24: 0.0037003956 | F24: 0.011053985 | G24: 0.00010871929 | H24: 0.0037174721 | I24: 0.013691932 | J24: 0.0032140561 | K24: 0.015463918 | L24: 0.0088997257 | N24: {=TRANSPOSE(O2:X2)} -> AAPL | O24: {=TRANSPOSE(O5:X5)} -> 1.0350111 | P24: 1
B25: -0.0024554942 | C25: 0 | D25: 0.0056818182 | E25: 0.00088990592 | F25: -0.010678871 | G25: -0.0056527883 | H25: -0.0063492063 | I25: -0.0038591413 | J25: -0.0010679197 | K25: 0.025380711 | L25: 0.0011026524 | N25: KO | O25: 0.60813159 | P25: 1
B26: 0.010461538 | C26: 0.0035377358 | D26: 0.02259887 | E26: 0.016131081 | F26: 0.028013364 | G26: 0.011041872 | H26: 0.0074547391 | I26: 0.0014527845 | J26: 0.014432328 | K26: 0.02970297 | L26: 0.014605368 | N26: NFLX | O26: 1.2517887 | P26: 1
B27: 0.009135201 | C27: -0.00058754407 | D27: 0.022099448 | E27: -0.001875 | F27: 0.0115 | G27: -0.0042711938 | H27: 0.0079281184 | I27: -0.002417795 | J27: 0.0015807777 | K27: 0.019230769 | L27: -0.00042382333 | N27: BRKB | O27: 0.93631496 | P27: 1
B28: 0.010259505 | C28: 0.0076425632 | D28: -0.010810811 | E28: 0.00037570445 | F28: 0.0128522 | G28: 0.0027691806 | H28: -0.0057682223 | I28: -0.0033931168 | J28: 0.0068392256 | K28: -0.0047169811 | L28: 0.0020233127 | N28: DIS | O28: 0.95595096 | P28: 1
B29: 0.016726404 | C29: -0.0032088681 | D29: -0.032786885 | E29: -0.0027541312 | F29: 0.0070766227 | G29: -0.0020576132 | H29: 0 | I29: -0.00097276265 | J29: 0.0031351238 | K29: 0.009478673 | L29: 0.0021602762 | N29: IBM | O29: 0.87200231 | P29: 1
B30: 0.0346651 | C30: -0.0052677788 | D30: 0.0056497175 | E30: -0.0057745418 | F30: 0.0062999758 | G30: 0.00092240912 | H30: 0 | I30: 0.0053554041 | J30: -0.0057297635 | K30: 0.018779343 | L30: 0.0014741178 | N30: VZ | O30: 0.6396436 | P30: 1
B31: 0.00056785917 | C31: -0.00058840836 | D31: -0.0056179775 | E31: -0.0051767677 | F31: -0.0019263183 | G31: -0.0036862362 | H31: -0.0060654008 | I31: -0.000968523 | J31: -0.01330679 | K31: -0.046082949 | L31: -0.0068863493 | N31: WMT | O31: 0.55286673 | P31: 1
B32: 0.018728717 | C32: 0.0073594348 | D32: -0.04519774 | E32: 0.0082497779 | F32: 0.0082026538 | G32: 0.0010337886 | H32: 0.011674184 | I32: -0.0014541929 | J32: 0.01030052 | K32: 0.014492754 | L32: 0.0068000358 | N32: GE | O32: 1.0133037 | P32: 1
B33: 0.013927577 | C33: 0.0067212157 | D33: 0.041420118 | E33: -0.0065458207 | F33: -0.0045465422 | G33: -0.0020654419 | H33: -0.0023603462 | I33: 0.0067961165 | J33: -0.006832037 | K33: 0.052380952 | L33: -0.00093950894 | N33: TSLA | O33: 1.3717635 | P33: 1
B34: -0.023626374 | C34: -0.007256894 | D34: -0.011363636 | E34: -0.0107704 | F34: -0.0084134615 | G34: 0.00016339869 | H34: -0.0055205047 | I34: -0.0072324012 | J34: -0.0095248174 | K34: 0.013574661 | L34: -0.0053831914
B35: 0.0095666854 | C35: 0.0067251462 | D35: 0 | E35: 0.010759575 | F35: 0.007030303 | G35: 0.0040298426 | H35: 0.0058154904 | I35: 0.0043710539 | J35: 0.013356128 | K35: 0.017857143 | L35: 0.011025662
B36: -0.0005574136 | C36: 0.0029044438 | D36: 0 | E36: 0.0064630592 | F36: 0.0050553683 | G36: 0.0020610728 | H36: 0.010775296 | I36: 0.0072533849 | J36: 0.0142345 | K36: 0.021929825 | L36: 0.0023489735
B37: 0.025655326 | C37: -0.0034752389 | D37: -0.034482759 | E37: 0.0026441702 | F37: -0.0043113772 | G37: -0.0001623816 | H37: 0.0007800312 | I37: -0.038886222 | J37: 0.0067574592 | K37: -0.012875536 | L37: 0.00071993712
B38: -0.0038064165 | C38: 0.0063934903 | D38: -0.041666667 | E38: -0.0087906568 | F38: -0.0072167428 | G38: 0.0024902555 | H38: -0.0072746168 | I38: -0.024475524 | J38: -0.0010326311 | K38: -0.0086956522 | L38: -0.0033401605
B39: 0.0065502183 | C39: -0.0011550679 | D39: 0 | E39: 0.0055745597 | F39: 0.005088442 | G39: 0.01927854 | H39: -0.0020936928 | I39: -0.0010240655 | J39: -0.0041347943 | K39: 0.0087719298 | L39: 0.0042720563
B40: 0.011930586 | C40: -0.0026019081 | D40: -0.0062111801 | E40: 0.0084414766 | F40: -0.0040983607 | G40: 0.00074172185 | H40: 0.00026226069 | I40: 0.004613019 | J40: -0.0036329666 | K40: -0.02173913 | L40: 0.0016722163
B41: 0.0064308682 | C41: -0.0023188406 | D41: -0.025 | E41: 0.0026236882 | F41: 0.0079883805 | G41: -0.001164699 | H41: -0.00026219192 | I41: -0.0056122449 | J41: -0.0088550891 | K41: -0.0044444444 | L41: 0.001354577
B42: 0.018104366 | C42: 0 | D42: 0.038461538 | E42: -0.010093458 | F42: 0.0069644573 | G42: 0.0022791117 | H42: 0.00052452137 | I42: 0.0076962545 | J42: 0.0047298718 | K42: 0.0044642857 | L42: 0.0033562691
...

Sheet Two Stock Portfolio
D3: Average Return | E3: Annualized Return | F3: Risk / Stdev of Individual Stock | G3: Annualized STDEV | H3: Above Market Returns
C4: AAPL | D4: =AVERAGE('Closing Price Data & Returns '!AI6:AI1513) -> 0.00082509413 | E4: =D4*250 -> 0.20627353 | F4: =_xlfn.STDEV.S('Closing Price Data & Returns '!AI6:AI1513) -> 0.015696405 | G4: =F4*SQRT(250) -> 0.24818195 | H4: =E4-$E$14 -> 0.076578045
C5: KO | D5: =AVERAGE('Closing Price Data & Returns '!AJ6:AJ1513) -> 0.00021593065 | E5: =D5*250 -> 0.053982662 | F5: =_xlfn.STDEV.S('Closing Price Data & Returns '!AJ6:AJ1513) -> 0.0086837977 | G5: =F5*SQRT(250) -> 0.1373029 | H5: =E5-$E$14 -> -0.075712827
C6: NFLX | D6: =AVERAGE('Closing Price Data & Returns '!AK6:AK1513) -> 0.0024538896 | E6: =D6*250 -> 0.61347239 | F6: =_xlfn.STDEV.S('Closing Price Data & Returns '!AK6:AK1513) -> 0.03257915 | G6: =F6*SQRT(250) -> 0.51512159 | H6: =E6-$E$14 -> 0.48377691
C7: BRK.B | D7: =AVERAGE('Closing Price Data & Returns '!AL6:AL1513) -> 0.00066112187 | E7: =D7*250 -> 0.16528047 | F7: =_xlfn.STDEV.S('Closing Price Data & Returns '!AL6:AL1513) -> 0.008922499 | G7: =F7*SQRT(250) -> 0.1410771 | H7: =E7-$E$14 -> 0.035584979
C8: DIS | D8: =AVERAGE('Closing Price Data & Returns '!AM6:AM1513) -> 0.00075044785 | E8: =D8*250 -> 0.18761196 | F8: =_xlfn.STDEV.S('Closing Price Data & Returns '!AM6:AM1513) -> 0.011471059 | G8: =F8*SQRT(250) -> 0.18137337 | H8: =E8-$E$14 -> 0.057916473
C9: IBM | D9: =AVERAGE('Closing Price Data & Returns '!AN6:AN1513) -> -6.2442054e-05 | E9: =D9*250 -> -0.015610513 | F9: =_xlfn.STDEV.S('Closing Price Data & Returns '!AN6:AN1513) -> 0.011494934 | G9: =F9*SQRT(250) -> 0.18175087 | H9: =E9-$E$14 -> -0.145306
C10: VZ | D10: =AVERAGE('Closing Price Data & Returns '!AO6:AO1513) -> 0.0002415176 | E10: =D10*250 -> 0.0603794 | F10: =_xlfn.STDEV.S('Closing Price Data & Returns '!AO6:AO1513) -> 0.010136588 | G10: =F10*SQRT(250) -> 0.16027354 | H10: =E10-$E$14 -> -0.069316089
C11: WMT | D11: =AVERAGE('Closing Price Data & Returns '!AP6:AP1513) -> 0.00038410406 | E11: =D11*250 -> 0.096026016 | F11: =_xlfn.STDEV.S('Closing Price Data & Returns '!AP6:AP1513) -> 0.010712912 | G11: =F11*SQRT(250) -> 0.16938601 | H11: =E11-$E$14 -> -0.033669473
C12: GE | D12: =AVERAGE('Closing Price Data & Returns '!AQ6:AQ1513) -> 3.4261518e-05 | E12: =D12*250 -> 0.0085653795 | F12: =_xlfn.STDEV.S('Closing Price Data & Returns '!AQ6:AQ1513) -> 0.011672011 | G12: =F12*SQRT(250) -> 0.1845507 | H12: =E12-$E$14 -> -0.12113011
C13: TSLA | D13: =AVERAGE('Closing Price Data & Returns '!AR6:AR1513) -> 0.0020585426 | E13: =D13*250 -> 0.51463565 | F13: =_xlfn.STDEV.S('Closing Price Data & Returns '!AR6:AR1513) -> 0.030520698 | G13: =F13*SQRT(250) -> 0.48257461 | H13: =E13-$E$14 -> 0.38494016
C14: S&P 500 | D14: =AVERAGE('Closing Price Data & Returns '!AS6:AS1513) -> 0.00051878196 | E14: =D14*250 -> 0.12969549 | F14: =_xlfn.STDEV.S('Closing Price Data & Returns '!AS6:AS1513) -> 0.0075743905 | G14: =F14*SQRT(250) -> 0.11976163
C16: 2 Stock Portfolios
C18: Portfolio 1: AAPL & KO
C20: Portfolio | D20: Weight of AAPL | E20: Weight of KO | F20: Return AAPL | G20: Retrun KO | H20: Variance of AAPL | I20: Variance KO | J20: COVAR (AAPL,KO) | K20: Portfolio Varaince | L20: Portfolio STDEV | M20: Annualized STDEV | N20: Portfolio Annual Return | V20: Portfolio 1: AAPL & KO: This portfolio combines a high-growth technology stock (AAPL) with a defensive consumer staples stock (KO). The results show that adding KO significantly reduces portfolio volatility compared to holding AAPL alone. The minimum variance portfolio occurs at approximately 20% AAPL and 80% KO, demonstrating the diversification benefit of combining growth and defensive assets.
C21: 1 | D21: 0.1 | E21: =1-D21 -> 0.9 | F21: =E4 -> 0.20627353 | G21: =E5 -> 0.053982662 | H21: ='Calculating the Individual BETA'!O3 -> 0.00024637712 | I21: ='Calculating the Individual BETA'!P3 -> 7.5408343e-05 | J21: =COVAR('Closing Price Data & Returns '!AI6:AI1513,'Closing Price Data & Returns '!AJ6:AJ1513) -> 2.8028038e-05 | K21: =(D21*D21*H21)+(E21*E21*I21)+(2*J21*D21*E21) -> 6.8589576e-05 | L21: =SQRT(K21) -> 0.0082818824 | M21: =L21*SQRT(250) -> 0.13094806 | N21: =(D21*F21)+(E21*G21) -> 0.06921175
C22: 2 | D22: 0.2 | E22: =1-D22 -> 0.8 | F22: =F21 -> 0.20627353 | G22: =G21 -> 0.053982662 | H22: =H21 -> 0.00024637712 | I22: =I21 -> 7.5408343e-05 | J22: =J21 -> 2.8028038e-05 | K22: =(D22*D22*H22)+(E22*E22*I22)+(2*J22*D22*E22) -> 6.7085396e-05 | L22: =SQRT(K22) -> 0.0081905675 | M22: =L22*SQRT(250) -> 0.12950424 | N22: =(D22*F22)+(E22*G22) -> 0.084440837
C23: 3 | D23: 0.3 | E23: =1-D23 -> 0.7 | F23: =F22 -> 0.20627353 | G23: =G22 -> 0.053982662 | H23: =H22 -> 0.00024637712 | I23: =I22 -> 7.5408343e-05 | J23: =J22 -> 2.8028038e-05 | K23: =(D23*D23*H23)+(E23*E23*I23)+(2*J23*D23*E23) -> 7.0895805e-05 | L23: =SQRT(K23) -> 0.0084199646 | M23: =L23*SQRT(250) -> 0.13313133 | N23: =(D23*F23)+(E23*G23) -> 0.099669924
C24: 4 | D24: 0.4 | E24: =1-D24 -> 0.6 | F24: =F23 -> 0.20627353 | G24: =G23 -> 0.053982662 | H24: =H23 -> 0.00024637712 | I24: =I23 -> 7.5408343e-05 | J24: =J23 -> 2.8028038e-05 | K24: =(D24*D24*H24)+(E24*E24*I24)+(2*J24*D24*E24) -> 8.0020801e-05 | L24: =SQRT(K24) -> 0.0089454346 | M24: =L24*SQRT(250) -> 0.14143974 | N24: =(D24*F24)+(E24*G24) -> 0.11489901
C25: 5 | D25: 0.5 | E25: =1-D25 -> 0.5 | F25: =F24 -> 0.20627353 | G25: =G24 -> 0.053982662 | H25: =H24 -> 0.00024637712 | I25: =I24 -> 7.5408343e-05 | J25: =J24 -> 2.8028038e-05 | K25: =(D25*D25*H25)+(E25*E25*I25)+(2*J25*D25*E25) -> 9.4460384e-05 | L25: =SQRT(K25) -> 0.0097190732 | M25: =L25*SQRT(250) -> 0.15367204 | N25: =(D25*F25)+(E25*G25) -> 0.1301281
C26: 6 | D26: 0.6 | E26: =1-D26 -> 0.4 | F26: =F25 -> 0.20627353 | G26: =G25 -> 0.053982662 | H26: =H25 -> 0.00024637712 | I26: =I25 -> 7.5408343e-05 | J26: =J25 -> 2.8028038e-05 | K26: =(D26*D26*H26)+(E26*E26*I26)+(2*J26*D26*E26) -> 0.00011421456 | L26: =SQRT(K26) -> 0.010687121 | M26: =L26*SQRT(250) -> 0.16897822 | N26: =(D26*F26)+(E26*G26) -> 0.14535719
C27: 7 | D27: 0.7 | E27: =1-D27 -> 0.3 | F27: =F26 -> 0.20627353 | G27: =G26 -> 0.053982662 | H27: =H26 -> 0.00024637712 | I27: =I26 -> 7.5408343e-05 | J27: =J26 -> 2.8028038e-05 | K27: =(D27*D27*H27)+(E27*E27*I27)+(2*J27*D27*E27) -> 0.00013928331 | L27: =SQRT(K27) -> 0.011801835 | M27: =L27*SQRT(250) -> 0.1866034 | N27: =(D27*F27)+(E27*G27) -> 0.16058627
C28: 8 | D28: 0.8 | E28: =1-D28 -> 0.2 | F28: =F27 -> 0.20627353 | G28: =G27 -> 0.053982662 | H28: =H27 -> 0.00024637712 | I28: =I27 -> 7.5408343e-05 | J28: =J27 -> 2.8028038e-05 | K28: =(D28*D28*H28)+(E28*E28*I28)+(2*J28*D28*E28) -> 0.00016966666 | L28: =SQRT(K28) -> 0.013025616 | M28: =L28*SQRT(250) -> 0.20595307 | N28: =(D28*F28)+(E28*G28) -> 0.17581536
C29: 9 | D29: 0.9 | E29: =1-D29 -> 0.1 | F29: =F28 -> 0.20627353 | G29: =G28 -> 0.053982662 | H29: =H28 -> 0.00024637712 | I29: =I28 -> 7.5408343e-05 | J29: =J28 -> 2.8028038e-05 | K29: =(D29*D29*H29)+(E29*E29*I29)+(2*J29*D29*E29) -> 0.0002053646 | L29: =SQRT(K29) -> 0.014330548 | M29: =L29*SQRT(250) -> 0.22658585 | N29: =(D29*F29)+(E29*G29) -> 0.19104445
C30: 10 | D30: 1 | E30: =1-D30 -> 0 | F30: =F29 -> 0.20627353 | G30: =G29 -> 0.053982662 | H30: =H29 -> 0.00024637712 | I30: =I29 -> 7.5408343e-05 | J30: =J29 -> 2.8028038e-05 | K30: =(D30*D30*H30)+(E30*E30*I30)+(2*J30*D30*E30) -> 0.00024637712 | L30: =SQRT(K30) -> 0.015696405 | M30: =L30*SQRT(250) -> 0.24818195 | N30: =(D30*F30)+(E30*G30) -> 0.20627353
J32: MVP | K32: =MIN(K21:K30) -> 6.7085396e-05
C34: Portfolio 2: TSLA & WMT
C36: Portfolio | D36: Weight of TSLA | E36: Weight of WMT | F36: Return TSLA | G36: Retrun WMT | H36: Variance of TSLA | I36: Variance WMT | J36: COVAR (TSLA,WMT) | K36: Portfolio Varaince | L36: Portfolio STDEV | M36: Annualized STDEV | N36: Portfolio Annual Return | V36: Portfolio 2: TSLA & WMT: This portfolio pairs Tesla, a high-volatility growth stock, with Walmart, a relatively stable retail company. As the weight of TSLA increases, both portfolio return and risk increase significantly. The efficient frontier clearly shows the trade-off between risk and return, while allocating more weight to WMT helps reduce portfolio volatility.
C37: 1 | D37: 0.1 | E37: =1-D37 -> 0.9 | F37: =$E$13 -> 0.51463565 | G37: =$E$11 -> 0.096026016 | H37: ='Calculating the Individual BETA'!X3 -> 0.00093151303 | I37: ='Calculating the Individual BETA'!V3 -> 0.00011476648 | J37: =COVAR('Closing Price Data & Returns '!AR6:AR1513,'Closing Price Data & Returns '!AP6:AP1513) -> 3.5483768e-05 | K37: =(D37*D37*H37)+(E37*E37*I37)+(2*J37*D37*E37) -> 0.00010866306 | L37: =SQRT(K37) -> 0.010424157 | M37: =L37*SQRT(250) -> 0.1648204 | N37: =(D37*F37)+(E37*G37) -> 0.13788698
C38: 2 | D38: 0.2 | E38: =1-D38 -> 0.8 | F38: =$E$13 -> 0.51463565 | G38: =$E$11 -> 0.096026016 | H38: =H37 -> 0.00093151303 | I38: =I37 -> 0.00011476648 | J38: =J37 -> 3.5483768e-05 | K38: =(D38*D38*H38)+(E38*E38*I38)+(2*J38*D38*E38) -> 0.00012206587 | L38: =SQRT(K38) -> 0.011048343 | M38: =L38*SQRT(250) -> 0.17468963 | N38: =(D38*F38)+(E38*G38) -> 0.17974794
C39: 3 | D39: 0.3 | E39: =1-D39 -> 0.7 | F39: =$E$13 -> 0.51463565 | G39: =$E$11 -> 0.096026016 | H39: =H38 -> 0.00093151303 | I39: =I38 -> 0.00011476648 | J39: =J38 -> 3.5483768e-05 | K39: =(D39*D39*H39)+(E39*E39*I39)+(2*J39*D39*E39) -> 0.00015497493 | L39: =SQRT(K39) -> 0.012448893 | M39: =L39*SQRT(250) -> 0.19683428 | N39: =(D39*F39)+(E39*G39) -> 0.22160891
C40: 4 | D40: 0.4 | E40: =1-D40 -> 0.6 | F40: =$E$13 -> 0.51463565 | G40: =$E$11 -> 0.096026016 | H40: =H39 -> 0.00093151303 | I40: =I39 -> 0.00011476648 | J40: =J39 -> 3.5483768e-05 | K40: =(D40*D40*H40)+(E40*E40*I40)+(2*J40*D40*E40) -> 0.00020739023 | L40: =SQRT(K40) -> 0.014401049 | M40: =L40*SQRT(250) -> 0.22770059 | N40: =(D40*F40)+(E40*G40) -> 0.26346987
C41: 5 | D41: 0.5 | E41: =1-D41 -> 0.5 | F41: =$E$13 -> 0.51463565 | G41: =$E$11 -> 0.096026016 | H41: =H40 -> 0.00093151303 | I41: =I40 -> 0.00011476648 | J41: =J40 -> 3.5483768e-05 | K41: =(D41*D41*H41)+(E41*E41*I41)+(2*J41*D41*E41) -> 0.00027931176 | L41: =SQRT(K41) -> 0.016712623 | M41: =L41*SQRT(250) -> 0.26424977 | N41: =(D41*F41)+(E41*G41) -> 0.30533083
C42: 6 | D42: 0.6 | E42: =1-D42 -> 0.4 | F42: =$E$13 -> 0.51463565 | G42: =$E$11 -> 0.096026016 | H42: =H41 -> 0.00093151303 | I42: =I41 -> 0.00011476648 | J42: =J41 -> 3.5483768e-05 | K42: =(D42*D42*H42)+(E42*E42*I42)+(2*J42*D42*E42) -> 0.00037073954 | L42: =SQRT(K42) -> 0.019254598 | M42: =L42*SQRT(250) -> 0.30444192 | N42: =(D42*F42)+(E42*G42) -> 0.3471918
C43: 7 | D43: 0.7 | E43: =1-D43 -> 0.3 | F43: =$E$13 -> 0.51463565 | G43: =$E$11 -> 0.096026016 | H43: =H42 -> 0.00093151303 | I43: =I42 -> 0.00011476648 | J43: =J42 -> 3.5483768e-05 | K43: =(D43*D43*H43)+(E43*E43*I43)+(2*J43*D43*E43) -> 0.00048167355 | L43: =SQRT(K43) -> 0.021947062 | M43: =L43*SQRT(250) -> 0.34701353 | N43: =(D43*F43)+(E43*G43) -> 0.38905276
C44: 8 | D44: 0.8 | E44: =1-D44 -> 0.2 | F44: =$E$13 -> 0.51463565 | G44: =$E$11 -> 0.096026016 | H44: =H43 -> 0.00093151303 | I44: =I43 -> 0.00011476648 | J44: =J43 -> 3.5483768e-05 | K44: =(D44*D44*H44)+(E44*E44*I44)+(2*J44*D44*E44) -> 0.00061211381 | L44: =SQRT(K44) -> 0.024740934 | M44: =L44*SQRT(250) -> 0.39118851 | N44: =(D44*F44)+(E44*G44) -> 0.43091372
C45: 9 | D45: 0.9 | E45: =1-D45 -> 0.1 | F45: =$E$13 -> 0.51463565 | G45: =$E$11 -> 0.096026016 | H45: =H44 -> 0.00093151303 | I45: =I44 -> 0.00011476648 | J45: =J44 -> 3.5483768e-05 | K45: =(D45*D45*H45)+(E45*E45*I45)+(2*J45*D45*E45) -> 0.0007620603 | L45: =SQRT(K45) -> 0.02760544 | M45: =L45*SQRT(250) -> 0.43648033 | N45: =(D45*F45)+(E45*G45) -> 0.47277469
C46: 10 | D46: 1 | E46: =1-D46 -> 0 | F46: =$E$13 -> 0.51463565 | G46: =$E$11 -> 0.096026016 | H46: =H45 -> 0.00093151303 | I46: =I45 -> 0.00011476648 | J46: =J45 -> 3.5483768e-05 | K46: =(D46*D46*H46)+(E46*E46*I46)+(2*J46*D46*E46) -> 0.00093151303 | L46: =SQRT(K46) -> 0.030520698 | M46: =L46*SQRT(250) -> 0.48257461 | N46: =(D46*F46)+(E46*G46) -> 0.51463565
J48: MVP | K48: =MIN(K37:K46) -> 0.00010866306
C51: Portfolio 3: NFLX & VZ
...

Sheet Portfolio Equal Weight
A2: Number of Stocks | B2: 10
D3: AAPL | E3: KO | F3: NFLX | G3: BRK.B | H3: DIS | I3: IBM | J3: VZ | K3: WMT | L3: GE | M3: TSLA
C4: Expected Return | D4: =AVERAGE('[1]Closing Price Data & Returns '!AG6:AG1513) -> 0.00082509413 | E4: =AVERAGE('[1]Closing Price Data & Returns '!AH6:AH1513) -> 0.00021593065 | F4: =AVERAGE('[1]Closing Price Data & Returns '!AI6:AI1513) -> 0.0024538896 | G4: =AVERAGE('[1]Closing Price Data & Returns '!AJ6:AJ1513) -> 0.00066112187 | H4: =AVERAGE('[1]Closing Price Data & Returns '!AK6:AK1513) -> 0.00075044785 | I4: =AVERAGE('[1]Closing Price Data & Returns '!AL6:AL1513) -> -6.2442054e-05 | J4: =AVERAGE('[1]Closing Price Data & Returns '!AM6:AM1513) -> 0.0002415176 | K4: =AVERAGE('[1]Closing Price Data & Returns '!AN6:AN1513) -> 0.00038410406 | ... M4: =AVERAGE('[1]Closing Price Data & Returns '!AP6:AP1513) -> 0.0020585426
C5: Variance of Ind Returns | D5: =_xlfn.VAR.S('[1]Closing Price Data & Returns '!AG6:AG1513) -> 0.00024637712 | E5: =_xlfn.VAR.S('[1]Closing Price Data & Returns '!AH6:AH1513) -> 7.5408343e-05 | F5: =_xlfn.VAR.S('[1]Closing Price Data & Returns '!AI6:AI1513) -> 0.001061401 | G5: =_xlfn.VAR.S('[1]Closing Price Data & Returns '!AJ6:AJ1513) -> 7.9610989e-05 | H5: =_xlfn.VAR.S('[1]Closing Price Data & Returns '!AK6:AK1513) -> 0.00013158519 | I5: =_xlfn.VAR.S('[1]Closing Price Data & Returns '!AL6:AL1513) -> 0.00013213351 | J5: =_xlfn.VAR.S('[1]Closing Price Data & Returns '!AM6:AM1513) -> 0.00010275043 | K5: =_xlfn.VAR.S('[1]Closing Price Data & Returns '!AN6:AN1513) -> 0.00011476648 | ... M5: =_xlfn.VAR.S('[1]Closing Price Data & Returns '!AP6:AP1513) -> 0.00093151303
C6: STDEV | D6: =SQRT(D5) -> 0.015696405 | E6: =SQRT(E5) -> 0.0086837977 | F6: =SQRT(F5) -> 0.03257915 | G6: =SQRT(G5) -> 0.008922499 | H6: =SQRT(H5) -> 0.011471059 | I6: =SQRT(I5) -> 0.011494934 | J6: =SQRT(J5) -> 0.010136588 | K6: =SQRT(K5) -> 0.010712912 | ... M6: =SQRT(M5) -> 0.030520698
C7: Annualized STDEV | D7: =D6*SQRT(250) -> 0.24818195 | E7: =E6*SQRT(250) -> 0.1373029 | F7: =F6*SQRT(250) -> 0.51512159 | G7: =G6*SQRT(250) -> 0.1410771 | H7: =H6*SQRT(250) -> 0.18137337 | I7: =I6*SQRT(250) -> 0.18175087 | J7: =J6*SQRT(250) -> 0.16027354 | K7: =K6*SQRT(250) -> 0.16938601 | ... M7: =M6*SQRT(250) -> 0.48257461
C8: BETA | D8: 1.0350111 | E8: 0.60813159 | F8: 1.2517887 | G8: 0.93631496 | H8: 0.95595096 | I8: 0.87200231 | J8: 0.6396436 | K8: 0.55286673 | L8: 1.0133037 | M8: 1.3717635
B10: Weight Allocation | E10: VAR COVAR MATRIX CALCULATION
B11: Ticker | C11: Weights | F11: {=TRANSPOSE(E12:E21)} -> AAPL | G11: KO | H11: NFLX | I11: BRK.B | J11: DIS | K11: IBM | L11: VZ | M11: WMT | N11: GE | O11: TSLA | R11: Individual Varainces
B12: {=TRANSPOSE(D3:M3)} -> AAPL | C12: =1/$B$2 -> 0.1 | E12: =B12 -> AAPL | F12: {=MMULT(TRANSPOSE('[1]Closing Price Data & Returns '!AG6:AP1513-'Portfolio Equal Weight'!D4:M4),'[1]Closing Price Data & Returns '!AG6:AP1513-'Portfolio Equal Weight'!D4:M4)/(1508-1)} -> 0.00024637712 | G12: 2.8046637e-05 | H12: 5.8010339e-05 | I12: 4.4000634e-05 | J12: 4.7834345e-05 | K12: 4.7591207e-05 | L12: 2.6818444e-05 | M12: 2.8881236e-05 | N12: 4.6881654e-05 | O12: 9.4809336e-05 | R12: Covariance
B13: KO | C13: =1/$B$2 -> 0.1 | E13: =B13 -> KO | F13: 2.8046637e-05 | G13: 7.5408343e-05 | H13: 2.5332789e-05 | I13: 3.6593772e-05 | J13: 3.6741279e-05 | K13: 3.2004512e-05 | L13: 3.2584312e-05 | M13: 2.8866027e-05 | N13: 3.5304388e-05 | O13: 3.817079e-05
B14: NFLX | C14: =1/$B$2 -> 0.1 | E14: =B14 -> NFLX | F14: 5.8010339e-05 | G14: 2.5332789e-05 | H14: 0.001061401 | I14: 5.3752768e-05 | J14: 5.7977168e-05 | K14: 4.5686897e-05 | L14: 1.5017811e-05 | M14: 3.5225749e-05 | N14: 5.9356371e-05 | O14: 0.00023198374
B15: BRK.B | C15: =1/$B$2 -> 0.1 | E15: =B15 -> BRK.B | F15: 4.4000634e-05 | G15: 3.6593772e-05 | H15: 5.3752768e-05 | I15: 7.9610989e-05 | J15: 5.5114094e-05 | K15: 4.9654066e-05 | L15: 3.7624206e-05 | M15: 3.1826817e-05 | N15: 5.7106604e-05 | O15: 6.0139838e-05
B16: DIS | C16: =1/$B$2 -> 0.1 | E16: =B16 -> DIS | F16: 4.7834345e-05 | G16: 3.6741279e-05 | H16: 5.7977168e-05 | I16: 5.5114094e-05 | J16: 0.00013158519 | K16: 4.5256834e-05 | L16: 3.9117355e-05 | M16: 3.354214e-05 | N16: 5.7846745e-05 | O16: 7.9794427e-05
B17: IBM | C17: =1/$B$2 -> 0.1 | E17: =B17 -> IBM | F17: 4.7591207e-05 | G17: 3.2004512e-05 | H17: 4.5686897e-05 | I17: 4.9654066e-05 | J17: 4.5256834e-05 | K17: 0.00013213351 | L17: 3.4602008e-05 | M17: 2.7818375e-05 | N17: 5.7066493e-05 | O17: 6.5115585e-05
B18: VZ | C18: =1/$B$2 -> 0.1 | E18: =B18 -> VZ | F18: 2.6818444e-05 | G18: 3.2584312e-05 | H18: 1.5017811e-05 | I18: 3.7624206e-05 | J18: 3.9117355e-05 | K18: 3.4602008e-05 | L18: 0.00010275043 | M18: 3.1676774e-05 | N18: 4.3832507e-05 | O18: 3.4235752e-05
B19: WMT | C19: =1/$B$2 -> 0.1 | E19: =B19 -> WMT | F19: 2.8881236e-05 | G19: 2.8866027e-05 | H19: 3.5225749e-05 | I19: 3.1826817e-05 | J19: 3.354214e-05 | K19: 2.7818375e-05 | L19: 3.1676774e-05 | M19: 0.00011476648 | N19: 3.0294979e-05 | O19: 3.5507314e-05
B20: GE | C20: =1/$B$2 -> 0.1 | E20: =B20 -> GE | F20: 4.6881654e-05 | G20: 3.5304388e-05 | H20: 5.9356371e-05 | I20: 5.7106604e-05 | J20: 5.7846745e-05 | K20: 5.7066493e-05 | L20: 4.3832507e-05 | M20: 3.0294979e-05 | N20: 0.00013623584 | O20: 6.6613673e-05
B21: TSLA | C21: =1/$B$2 -> 0.1 | E21: =B21 -> TSLA | F21: 9.4809336e-05 | G21: 3.817079e-05 | H21: 0.00023198374 | I21: 6.0139838e-05 | J21: 7.9794427e-05 | K21: 6.5115585e-05 | L21: 3.4235752e-05 | M21: 3.5507314e-05 | N21: 6.6613673e-05 | O21: 0.00093151303
B22: TOTAL | C22: =SUM(C12:C21) -> 1
A26: PORTFOLIO SUMMARY | E26: Interpretation:
A27: Metrics | B27: Daily | C27: Annual | E27: The equal weighted portfolio assigns an equal allocation of 10% to each of the 10 stocks, ensuring that every asset contributes equally to the overall portfolio composition. This approach removes bias toward larger or higher-performing stocks and provides a simple method of diversification. Using the variance–covariance matrix, the portfolio’s overall risk and return are calculated by incorporating both the individual variances of the stocks and the covariance between them. This allows the model to capture how assets move relative to one another, which is essential for understanding the true level of portfolio risk. The results show that the portfolio generates an expected annual return of 18.91% with an annualized volatility of 13.54%, indicating a relatively balanced risk–return profile. Compared with several high-volatility individual stocks such as TSLA and NFLX, the portfolio exhibits significantly lower risk due to the benefits of diversification. The Sharpe Ratio of 1.10 suggests that the portfolio provides strong risk-adjusted performance, meaning the return generated per unit of risk is favorable relative to the assumed 4% risk-free rate. The portfolio beta of 0.924 indicates that the portfolio is slightly less volatile than the overall market (S&P 500). Additionally, the positive Jensen’s Alpha of 6.62% implies that the portfolio delivers returns above those predicted by the Capital Asset Pricing Model (CAPM), suggesting potential outperformance relative to the market benchmark. Overall, the equal weighted portfolio demonstrates how diversification across multiple assets can reduce overall portfolio risk while still maintaining competitive returns, highlighting a key principle of modern portfolio theory.
A28: Variance of Portfolio | B28: {=MMULT(TRANSPOSE(C12:C21),MMULT(_xlfn.ANCHORARRAY(F12),C12:C21))} -> 7.3342995e-05
A29: STDEV (Risk) of Portfolio | B29: =SQRT(B28) -> 0.0085640525 | C29: =B29*SQRT(250) -> 0.13540956
A30: Expected Return of the Portfolio | B30: {=SUMPRODUCT(C12:C21,TRANSPOSE(D4:M4))} -> 0.00075624678 | C30: =B30*250 -> 0.1890617
A32: Risk Free Rate | B32: 0.04
A33: Sharpe Ratio | B33: =(C30-B32)/C29 -> 1.1008211
A34: Portfolio Beta | B34: {=SUMPRODUCT(C12:C21,TRANSPOSE(D8:M8))} -> 0.92367772
A35: Rm (S&P 500) | B35: ='Return&Risk of Individual Stock'!D14 -> 0.12969549
A36: Jenson Alpha | B36: =C30-(B32+B34*(B35-B32)) -> 0.066211971

Sheet Max Sharpe Ratio (Solver)
A2: Number of Stocks | B2: 10
D3: AAPL | E3: KO | F3: NFLX | G3: BRK.B | H3: DIS | I3: IBM | J3: VZ | K3: WMT | L3: GE | M3: TSLA
